[2024-07-10 00:39:24,169] {taskinstance.py:1159} INFO - Dependencies all met for <TaskInstance: create_layers_in_snowflake.create_seeds manual__2024-07-10T00:39:22.253613+00:00 [queued]>
[2024-07-10 00:39:24,178] {taskinstance.py:1159} INFO - Dependencies all met for <TaskInstance: create_layers_in_snowflake.create_seeds manual__2024-07-10T00:39:22.253613+00:00 [queued]>
[2024-07-10 00:39:24,179] {taskinstance.py:1356} INFO - 
--------------------------------------------------------------------------------
[2024-07-10 00:39:24,179] {taskinstance.py:1357} INFO - Starting attempt 1 of 1
[2024-07-10 00:39:24,179] {taskinstance.py:1358} INFO - 
--------------------------------------------------------------------------------
[2024-07-10 00:39:24,192] {taskinstance.py:1377} INFO - Executing <Task(DockerOperator): create_seeds> on 2024-07-10 00:39:22.253613+00:00
[2024-07-10 00:39:24,195] {standard_task_runner.py:52} INFO - Started process 591 to run task
[2024-07-10 00:39:24,199] {standard_task_runner.py:79} INFO - Running: ['***', 'tasks', 'run', 'create_layers_in_snowflake', 'create_seeds', 'manual__2024-07-10T00:39:22.253613+00:00', '--job-id', '5', '--raw', '--subdir', 'DAGS_FOLDER/create_layers.py', '--cfg-path', '/tmp/tmpz3dn_i6w', '--error-file', '/tmp/tmpnn3k3n1n']
[2024-07-10 00:39:24,199] {standard_task_runner.py:80} INFO - Job 5: Subtask create_seeds
[2024-07-10 00:39:24,255] {task_command.py:369} INFO - Running <TaskInstance: create_layers_in_snowflake.create_seeds manual__2024-07-10T00:39:22.253613+00:00 [running]> on host 9ba3cd856d5b
[2024-07-10 00:39:24,325] {taskinstance.py:1571} INFO - Exporting the following env vars:
AIRFLOW_CTX_DAG_OWNER=***
AIRFLOW_CTX_DAG_ID=create_layers_in_snowflake
AIRFLOW_CTX_TASK_ID=create_seeds
AIRFLOW_CTX_EXECUTION_DATE=2024-07-10T00:39:22.253613+00:00
AIRFLOW_CTX_TRY_NUMBER=1
AIRFLOW_CTX_DAG_RUN_ID=manual__2024-07-10T00:39:22.253613+00:00
[2024-07-10 00:39:24,345] {docker.py:247} INFO - Starting docker container from image custom_dbt_image
[2024-07-10 00:39:26,237] {docker.py:308} INFO - [0m00:39:26  Running with dbt=1.5.0
[2024-07-10 00:39:26,604] {docker.py:308} INFO - [0m00:39:26  Found 9 models, 0 tests, 0 snapshots, 0 analyses, 321 macros, 0 operations, 1 seed file, 0 sources, 0 exposures, 0 metrics, 0 groups
[2024-07-10 00:39:26,607] {docker.py:308} INFO - [0m00:39:26
[2024-07-10 00:39:28,527] {docker.py:308} INFO - [0m00:39:28  Concurrency: 1 threads (target='dev')
[2024-07-10 00:39:28,528] {docker.py:308} INFO - [0m00:39:28
[2024-07-10 00:39:28,530] {docker.py:308} INFO - [0m00:39:28  1 of 1 START seed file DEV.full_moon_dates ..................................... [RUN]
[2024-07-10 00:39:28,560] {docker.py:308} INFO - [0m00:39:28  [31mUnhandled error while executing [0m
[Errno 2] No such file or directory: '/dbtlearn/seeds/full_moon_dates.csv'
[2024-07-10 00:39:28,564] {docker.py:308} INFO - [0m00:39:28  1 of 1 ERROR loading seed file DEV.full_moon_dates ............................. [[31mERROR[0m in 0.03s]
[2024-07-10 00:39:28,631] {docker.py:308} INFO - [0m00:39:28
[2024-07-10 00:39:28,632] {docker.py:308} INFO - [0m00:39:28  Finished running 1 seed in 0 hours 0 minutes and 2.02 seconds (2.02s).
[2024-07-10 00:39:28,641] {docker.py:308} INFO - [0m00:39:28
[2024-07-10 00:39:28,641] {docker.py:308} INFO - [0m00:39:28  [31mCompleted with 1 error and 0 warnings:[0m
[2024-07-10 00:39:28,642] {docker.py:308} INFO - [0m00:39:28
[2024-07-10 00:39:28,642] {docker.py:308} INFO - [0m00:39:28  [33m[Errno 2] No such file or directory: '/dbtlearn/seeds/full_moon_dates.csv'[0m
[2024-07-10 00:39:28,643] {docker.py:308} INFO - [0m00:39:28
[2024-07-10 00:39:28,643] {docker.py:308} INFO - [0m00:39:28  Done. PASS=0 WARN=0 ERROR=1 SKIP=0 TOTAL=1
[2024-07-10 00:39:29,114] {taskinstance.py:1889} ERROR - Task failed with exception
Traceback (most recent call last):
  File "/home/airflow/.local/lib/python3.7/site-packages/airflow/providers/docker/operators/docker.py", line 387, in execute
    return self._run_image()
  File "/home/airflow/.local/lib/python3.7/site-packages/airflow/providers/docker/operators/docker.py", line 266, in _run_image
    return self._run_image_with_mounts(self.mounts, add_tmp_variable=False)
  File "/home/airflow/.local/lib/python3.7/site-packages/airflow/providers/docker/operators/docker.py", line 313, in _run_image_with_mounts
    raise AirflowException(f'Docker container failed: {repr(result)} lines {joined_log_lines}')
airflow.exceptions.AirflowException: Docker container failed: {'StatusCode': 1} lines [0m00:39:26  Running with dbt=1.5.0
[0m00:39:26  Found 9 models, 0 tests, 0 snapshots, 0 analyses, 321 macros, 0 operations, 1 seed file, 0 sources, 0 exposures, 0 metrics, 0 groups
[0m00:39:26
[0m00:39:28  Concurrency: 1 threads (target='dev')
[0m00:39:28
[0m00:39:28  1 of 1 START seed file DEV.full_moon_dates ..................................... [RUN]
[0m00:39:28  [31mUnhandled error while executing [0m
[Errno 2] No such file or directory: '/dbtlearn/seeds/full_moon_dates.csv'
[0m00:39:28  1 of 1 ERROR loading seed file DEV.full_moon_dates ............................. [[31mERROR[0m in 0.03s]
[0m00:39:28
[0m00:39:28  Finished running 1 seed in 0 hours 0 minutes and 2.02 seconds (2.02s).
[0m00:39:28
[0m00:39:28  [31mCompleted with 1 error and 0 warnings:[0m
[0m00:39:28
[0m00:39:28  [33m[Errno 2] No such file or directory: '/dbtlearn/seeds/full_moon_dates.csv'[0m
[0m00:39:28
[0m00:39:28  Done. PASS=0 WARN=0 ERROR=1 SKIP=0 TOTAL=1
[2024-07-10 00:39:29,117] {taskinstance.py:1400} INFO - Marking task as FAILED. dag_id=create_layers_in_snowflake, task_id=create_seeds, execution_date=20240710T003922, start_date=20240710T003924, end_date=20240710T003929
[2024-07-10 00:39:29,129] {standard_task_runner.py:97} ERROR - Failed to execute job 5 for task create_seeds (Docker container failed: {'StatusCode': 1} lines [0m00:39:26  Running with dbt=1.5.0
[0m00:39:26  Found 9 models, 0 tests, 0 snapshots, 0 analyses, 321 macros, 0 operations, 1 seed file, 0 sources, 0 exposures, 0 metrics, 0 groups
[0m00:39:26
[0m00:39:28  Concurrency: 1 threads (target='dev')
[0m00:39:28
[0m00:39:28  1 of 1 START seed file DEV.full_moon_dates ..................................... [RUN]
[0m00:39:28  [31mUnhandled error while executing [0m
[Errno 2] No such file or directory: '/dbtlearn/seeds/full_moon_dates.csv'
[0m00:39:28  1 of 1 ERROR loading seed file DEV.full_moon_dates ............................. [[31mERROR[0m in 0.03s]
[0m00:39:28
[0m00:39:28  Finished running 1 seed in 0 hours 0 minutes and 2.02 seconds (2.02s).
[0m00:39:28
[0m00:39:28  [31mCompleted with 1 error and 0 warnings:[0m
[0m00:39:28
[0m00:39:28  [33m[Errno 2] No such file or directory: '/dbtlearn/seeds/full_moon_dates.csv'[0m
[0m00:39:28
[0m00:39:28  Done. PASS=0 WARN=0 ERROR=1 SKIP=0 TOTAL=1; 591)
[2024-07-10 00:39:29,136] {local_task_job.py:156} INFO - Task exited with return code 1
[2024-07-10 00:39:29,182] {local_task_job.py:273} INFO - 0 downstream tasks scheduled from follow-on schedule check
