[2024-07-10 00:00:59,790] {taskinstance.py:1159} INFO - Dependencies all met for <TaskInstance: create_layers_in_snowflake.create_seeds manual__2024-07-10T00:00:58.726621+00:00 [queued]>
[2024-07-10 00:00:59,799] {taskinstance.py:1159} INFO - Dependencies all met for <TaskInstance: create_layers_in_snowflake.create_seeds manual__2024-07-10T00:00:58.726621+00:00 [queued]>
[2024-07-10 00:00:59,800] {taskinstance.py:1356} INFO - 
--------------------------------------------------------------------------------
[2024-07-10 00:00:59,800] {taskinstance.py:1357} INFO - Starting attempt 1 of 1
[2024-07-10 00:00:59,801] {taskinstance.py:1358} INFO - 
--------------------------------------------------------------------------------
[2024-07-10 00:00:59,814] {taskinstance.py:1377} INFO - Executing <Task(DockerOperator): create_seeds> on 2024-07-10 00:00:58.726621+00:00
[2024-07-10 00:00:59,818] {standard_task_runner.py:52} INFO - Started process 1879 to run task
[2024-07-10 00:00:59,821] {standard_task_runner.py:79} INFO - Running: ['***', 'tasks', 'run', 'create_layers_in_snowflake', 'create_seeds', 'manual__2024-07-10T00:00:58.726621+00:00', '--job-id', '25', '--raw', '--subdir', 'DAGS_FOLDER/create_layers.py', '--cfg-path', '/tmp/tmpbt2iz3wd', '--error-file', '/tmp/tmpqd5_3fsd']
[2024-07-10 00:00:59,822] {standard_task_runner.py:80} INFO - Job 25: Subtask create_seeds
[2024-07-10 00:00:59,877] {task_command.py:369} INFO - Running <TaskInstance: create_layers_in_snowflake.create_seeds manual__2024-07-10T00:00:58.726621+00:00 [running]> on host a22086a40575
[2024-07-10 00:00:59,949] {taskinstance.py:1571} INFO - Exporting the following env vars:
AIRFLOW_CTX_DAG_OWNER=***
AIRFLOW_CTX_DAG_ID=create_layers_in_snowflake
AIRFLOW_CTX_TASK_ID=create_seeds
AIRFLOW_CTX_EXECUTION_DATE=2024-07-10T00:00:58.726621+00:00
AIRFLOW_CTX_TRY_NUMBER=1
AIRFLOW_CTX_DAG_RUN_ID=manual__2024-07-10T00:00:58.726621+00:00
[2024-07-10 00:00:59,971] {docker.py:247} INFO - Starting docker container from image custom_dbt_image
[2024-07-10 00:00:59,995] {taskinstance.py:1889} ERROR - Task failed with exception
Traceback (most recent call last):
  File "/home/airflow/.local/lib/python3.7/site-packages/docker/api/client.py", line 268, in _raise_for_status
    response.raise_for_status()
  File "/home/airflow/.local/lib/python3.7/site-packages/requests/models.py", line 960, in raise_for_status
    raise HTTPError(http_error_msg, response=self)
requests.exceptions.HTTPError: 400 Client Error: Bad Request for url: http+docker://localhost/v1.45/containers/create

During handling of the above exception, another exception occurred:

Traceback (most recent call last):
  File "/home/airflow/.local/lib/python3.7/site-packages/airflow/providers/docker/operators/docker.py", line 387, in execute
    return self._run_image()
  File "/home/airflow/.local/lib/python3.7/site-packages/airflow/providers/docker/operators/docker.py", line 266, in _run_image
    return self._run_image_with_mounts(self.mounts, add_tmp_variable=False)
  File "/home/airflow/.local/lib/python3.7/site-packages/airflow/providers/docker/operators/docker.py", line 298, in _run_image_with_mounts
    tty=self.tty,
  File "/home/airflow/.local/lib/python3.7/site-packages/docker/api/container.py", line 428, in create_container
    return self.create_container_from_config(config, name)
  File "/home/airflow/.local/lib/python3.7/site-packages/docker/api/container.py", line 439, in create_container_from_config
    return self._result(res, True)
  File "/home/airflow/.local/lib/python3.7/site-packages/docker/api/client.py", line 274, in _result
    self._raise_for_status(response)
  File "/home/airflow/.local/lib/python3.7/site-packages/docker/api/client.py", line 270, in _raise_for_status
    raise create_api_error_from_http_exception(e)
  File "/home/airflow/.local/lib/python3.7/site-packages/docker/errors.py", line 31, in create_api_error_from_http_exception
    raise cls(e, response=response, explanation=explanation)
docker.errors.APIError: 400 Client Error for http+docker://localhost/v1.45/containers/create: Bad Request ("create /dbtlearn: "/dbtlearn" includes invalid characters for a local volume name, only "[a-zA-Z0-9][a-zA-Z0-9_.-]" are allowed. If you intended to pass a host directory, use absolute path")
[2024-07-10 00:01:00,007] {taskinstance.py:1400} INFO - Marking task as FAILED. dag_id=create_layers_in_snowflake, task_id=create_seeds, execution_date=20240710T000058, start_date=20240710T000059, end_date=20240710T000100
[2024-07-10 00:01:00,020] {standard_task_runner.py:97} ERROR - Failed to execute job 25 for task create_seeds (400 Client Error for http+docker://localhost/v1.45/containers/create: Bad Request ("create /dbtlearn: "/dbtlearn" includes invalid characters for a local volume name, only "[a-zA-Z0-9][a-zA-Z0-9_.-]" are allowed. If you intended to pass a host directory, use absolute path"); 1879)
[2024-07-10 00:01:00,043] {local_task_job.py:156} INFO - Task exited with return code 1
[2024-07-10 00:01:00,073] {local_task_job.py:273} INFO - 0 downstream tasks scheduled from follow-on schedule check
