[2024-07-10 00:58:15,005] {taskinstance.py:1159} INFO - Dependencies all met for <TaskInstance: create_layers_in_snowflake.create_seeds manual__2024-07-10T00:58:13.257991+00:00 [queued]>
[2024-07-10 00:58:15,014] {taskinstance.py:1159} INFO - Dependencies all met for <TaskInstance: create_layers_in_snowflake.create_seeds manual__2024-07-10T00:58:13.257991+00:00 [queued]>
[2024-07-10 00:58:15,014] {taskinstance.py:1356} INFO - 
--------------------------------------------------------------------------------
[2024-07-10 00:58:15,015] {taskinstance.py:1357} INFO - Starting attempt 1 of 1
[2024-07-10 00:58:15,015] {taskinstance.py:1358} INFO - 
--------------------------------------------------------------------------------
[2024-07-10 00:58:15,027] {taskinstance.py:1377} INFO - Executing <Task(DockerOperator): create_seeds> on 2024-07-10 00:58:13.257991+00:00
[2024-07-10 00:58:15,031] {standard_task_runner.py:52} INFO - Started process 1487 to run task
[2024-07-10 00:58:15,034] {standard_task_runner.py:79} INFO - Running: ['***', 'tasks', 'run', 'create_layers_in_snowflake', 'create_seeds', 'manual__2024-07-10T00:58:13.257991+00:00', '--job-id', '11', '--raw', '--subdir', 'DAGS_FOLDER/create_layers.py', '--cfg-path', '/tmp/tmpdey1t3f8', '--error-file', '/tmp/tmpyil4o20u']
[2024-07-10 00:58:15,035] {standard_task_runner.py:80} INFO - Job 11: Subtask create_seeds
[2024-07-10 00:58:15,090] {task_command.py:369} INFO - Running <TaskInstance: create_layers_in_snowflake.create_seeds manual__2024-07-10T00:58:13.257991+00:00 [running]> on host 9ba3cd856d5b
[2024-07-10 00:58:15,161] {taskinstance.py:1571} INFO - Exporting the following env vars:
AIRFLOW_CTX_DAG_OWNER=***
AIRFLOW_CTX_DAG_ID=create_layers_in_snowflake
AIRFLOW_CTX_TASK_ID=create_seeds
AIRFLOW_CTX_EXECUTION_DATE=2024-07-10T00:58:13.257991+00:00
AIRFLOW_CTX_TRY_NUMBER=1
AIRFLOW_CTX_DAG_RUN_ID=manual__2024-07-10T00:58:13.257991+00:00
[2024-07-10 00:58:15,183] {docker.py:247} INFO - Starting docker container from image custom_dbt_image
[2024-07-10 00:58:16,958] {docker.py:308} INFO - [0m00:58:16  Running with dbt=1.5.0
[2024-07-10 00:58:17,294] {docker.py:308} INFO - [0m00:58:17  Found 9 models, 0 tests, 0 snapshots, 0 analyses, 321 macros, 0 operations, 1 seed file, 0 sources, 0 exposures, 0 metrics, 0 groups
[2024-07-10 00:58:17,296] {docker.py:308} INFO - [0m00:58:17
[2024-07-10 00:58:19,042] {docker.py:308} INFO - [0m00:58:19  Concurrency: 1 threads (target='dev')
[2024-07-10 00:58:19,043] {docker.py:308} INFO - [0m00:58:19
[2024-07-10 00:58:19,047] {docker.py:308} INFO - [0m00:58:19  1 of 1 START seed file DEV.full_moon_dates ..................................... [RUN]
[2024-07-10 00:58:19,074] {docker.py:308} INFO - [0m00:58:19  [31mUnhandled error while executing [0m
[Errno 2] No such file or directory: '/dbtlearn/seeds/full_moon_dates.csv'
[2024-07-10 00:58:19,079] {docker.py:308} INFO - [0m00:58:19  1 of 1 ERROR loading seed file DEV.full_moon_dates ............................. [[31mERROR[0m in 0.03s]
[2024-07-10 00:58:19,147] {docker.py:308} INFO - [0m00:58:19
[2024-07-10 00:58:19,148] {docker.py:308} INFO - [0m00:58:19  Finished running 1 seed in 0 hours 0 minutes and 1.85 seconds (1.85s).
[2024-07-10 00:58:19,157] {docker.py:308} INFO - [0m00:58:19
[2024-07-10 00:58:19,157] {docker.py:308} INFO - [0m00:58:19  [31mCompleted with 1 error and 0 warnings:[0m
[2024-07-10 00:58:19,158] {docker.py:308} INFO - [0m00:58:19
[2024-07-10 00:58:19,159] {docker.py:308} INFO - [0m00:58:19  [33m[Errno 2] No such file or directory: '/dbtlearn/seeds/full_moon_dates.csv'[0m
[2024-07-10 00:58:19,159] {docker.py:308} INFO - [0m00:58:19
[2024-07-10 00:58:19,159] {docker.py:308} INFO - [0m00:58:19  Done. PASS=0 WARN=0 ERROR=1 SKIP=0 TOTAL=1
[2024-07-10 00:58:19,632] {taskinstance.py:1889} ERROR - Task failed with exception
Traceback (most recent call last):
  File "/home/airflow/.local/lib/python3.7/site-packages/airflow/providers/docker/operators/docker.py", line 387, in execute
    return self._run_image()
  File "/home/airflow/.local/lib/python3.7/site-packages/airflow/providers/docker/operators/docker.py", line 266, in _run_image
    return self._run_image_with_mounts(self.mounts, add_tmp_variable=False)
  File "/home/airflow/.local/lib/python3.7/site-packages/airflow/providers/docker/operators/docker.py", line 313, in _run_image_with_mounts
    raise AirflowException(f'Docker container failed: {repr(result)} lines {joined_log_lines}')
airflow.exceptions.AirflowException: Docker container failed: {'StatusCode': 1} lines [0m00:58:16  Running with dbt=1.5.0
[0m00:58:17  Found 9 models, 0 tests, 0 snapshots, 0 analyses, 321 macros, 0 operations, 1 seed file, 0 sources, 0 exposures, 0 metrics, 0 groups
[0m00:58:17
[0m00:58:19  Concurrency: 1 threads (target='dev')
[0m00:58:19
[0m00:58:19  1 of 1 START seed file DEV.full_moon_dates ..................................... [RUN]
[0m00:58:19  [31mUnhandled error while executing [0m
[Errno 2] No such file or directory: '/dbtlearn/seeds/full_moon_dates.csv'
[0m00:58:19  1 of 1 ERROR loading seed file DEV.full_moon_dates ............................. [[31mERROR[0m in 0.03s]
[0m00:58:19
[0m00:58:19  Finished running 1 seed in 0 hours 0 minutes and 1.85 seconds (1.85s).
[0m00:58:19
[0m00:58:19  [31mCompleted with 1 error and 0 warnings:[0m
[0m00:58:19
[0m00:58:19  [33m[Errno 2] No such file or directory: '/dbtlearn/seeds/full_moon_dates.csv'[0m
[0m00:58:19
[0m00:58:19  Done. PASS=0 WARN=0 ERROR=1 SKIP=0 TOTAL=1
[2024-07-10 00:58:19,636] {taskinstance.py:1400} INFO - Marking task as FAILED. dag_id=create_layers_in_snowflake, task_id=create_seeds, execution_date=20240710T005813, start_date=20240710T005815, end_date=20240710T005819
[2024-07-10 00:58:19,647] {standard_task_runner.py:97} ERROR - Failed to execute job 11 for task create_seeds (Docker container failed: {'StatusCode': 1} lines [0m00:58:16  Running with dbt=1.5.0
[0m00:58:17  Found 9 models, 0 tests, 0 snapshots, 0 analyses, 321 macros, 0 operations, 1 seed file, 0 sources, 0 exposures, 0 metrics, 0 groups
[0m00:58:17
[0m00:58:19  Concurrency: 1 threads (target='dev')
[0m00:58:19
[0m00:58:19  1 of 1 START seed file DEV.full_moon_dates ..................................... [RUN]
[0m00:58:19  [31mUnhandled error while executing [0m
[Errno 2] No such file or directory: '/dbtlearn/seeds/full_moon_dates.csv'
[0m00:58:19  1 of 1 ERROR loading seed file DEV.full_moon_dates ............................. [[31mERROR[0m in 0.03s]
[0m00:58:19
[0m00:58:19  Finished running 1 seed in 0 hours 0 minutes and 1.85 seconds (1.85s).
[0m00:58:19
[0m00:58:19  [31mCompleted with 1 error and 0 warnings:[0m
[0m00:58:19
[0m00:58:19  [33m[Errno 2] No such file or directory: '/dbtlearn/seeds/full_moon_dates.csv'[0m
[0m00:58:19
[0m00:58:19  Done. PASS=0 WARN=0 ERROR=1 SKIP=0 TOTAL=1; 1487)
[2024-07-10 00:58:19,680] {local_task_job.py:156} INFO - Task exited with return code 1
[2024-07-10 00:58:19,725] {local_task_job.py:273} INFO - 0 downstream tasks scheduled from follow-on schedule check
