[2024-07-10 00:31:05,354] {taskinstance.py:1159} INFO - Dependencies all met for <TaskInstance: create_layers_in_snowflake.create_seeds manual__2024-07-10T00:31:04.955286+00:00 [queued]>
[2024-07-10 00:31:05,364] {taskinstance.py:1159} INFO - Dependencies all met for <TaskInstance: create_layers_in_snowflake.create_seeds manual__2024-07-10T00:31:04.955286+00:00 [queued]>
[2024-07-10 00:31:05,364] {taskinstance.py:1356} INFO - 
--------------------------------------------------------------------------------
[2024-07-10 00:31:05,365] {taskinstance.py:1357} INFO - Starting attempt 1 of 1
[2024-07-10 00:31:05,365] {taskinstance.py:1358} INFO - 
--------------------------------------------------------------------------------
[2024-07-10 00:31:05,379] {taskinstance.py:1377} INFO - Executing <Task(DockerOperator): create_seeds> on 2024-07-10 00:31:04.955286+00:00
[2024-07-10 00:31:05,383] {standard_task_runner.py:52} INFO - Started process 201 to run task
[2024-07-10 00:31:05,387] {standard_task_runner.py:79} INFO - Running: ['***', 'tasks', 'run', 'create_layers_in_snowflake', 'create_seeds', 'manual__2024-07-10T00:31:04.955286+00:00', '--job-id', '3', '--raw', '--subdir', 'DAGS_FOLDER/create_layers.py', '--cfg-path', '/tmp/tmpjut5j8a8', '--error-file', '/tmp/tmpw43z6698']
[2024-07-10 00:31:05,387] {standard_task_runner.py:80} INFO - Job 3: Subtask create_seeds
[2024-07-10 00:31:05,447] {task_command.py:369} INFO - Running <TaskInstance: create_layers_in_snowflake.create_seeds manual__2024-07-10T00:31:04.955286+00:00 [running]> on host 9ba3cd856d5b
[2024-07-10 00:31:05,521] {taskinstance.py:1571} INFO - Exporting the following env vars:
AIRFLOW_CTX_DAG_OWNER=***
AIRFLOW_CTX_DAG_ID=create_layers_in_snowflake
AIRFLOW_CTX_TASK_ID=create_seeds
AIRFLOW_CTX_EXECUTION_DATE=2024-07-10T00:31:04.955286+00:00
AIRFLOW_CTX_TRY_NUMBER=1
AIRFLOW_CTX_DAG_RUN_ID=manual__2024-07-10T00:31:04.955286+00:00
[2024-07-10 00:31:05,543] {docker.py:247} INFO - Starting docker container from image custom_dbt_image
[2024-07-10 00:31:07,312] {docker.py:308} INFO - [0m00:31:07  Running with dbt=1.5.0
[2024-07-10 00:31:07,643] {docker.py:308} INFO - [0m00:31:07  Found 9 models, 0 tests, 0 snapshots, 0 analyses, 321 macros, 0 operations, 1 seed file, 0 sources, 0 exposures, 0 metrics, 0 groups
[2024-07-10 00:31:07,644] {docker.py:308} INFO - [0m00:31:07
[2024-07-10 00:31:09,390] {docker.py:308} INFO - [0m00:31:09  Concurrency: 1 threads (target='dev')
[2024-07-10 00:31:09,391] {docker.py:308} INFO - [0m00:31:09
[2024-07-10 00:31:09,395] {docker.py:308} INFO - [0m00:31:09  1 of 1 START seed file DEV.full_moon_dates ..................................... [RUN]
[2024-07-10 00:31:09,421] {docker.py:308} INFO - [0m00:31:09  [31mUnhandled error while executing [0m
[Errno 2] No such file or directory: '/dbtlearn/seeds/full_moon_dates.csv'
[2024-07-10 00:31:09,423] {docker.py:308} INFO - [0m00:31:09  1 of 1 ERROR loading seed file DEV.full_moon_dates ............................. [[31mERROR[0m in 0.03s]
[2024-07-10 00:31:09,495] {docker.py:308} INFO - [0m00:31:09
[2024-07-10 00:31:09,496] {docker.py:308} INFO - [0m00:31:09  Finished running 1 seed in 0 hours 0 minutes and 1.85 seconds (1.85s).
[2024-07-10 00:31:09,503] {docker.py:308} INFO - [0m00:31:09
[2024-07-10 00:31:09,504] {docker.py:308} INFO - [0m00:31:09  [31mCompleted with 1 error and 0 warnings:[0m
[2024-07-10 00:31:09,504] {docker.py:308} INFO - [0m00:31:09
[2024-07-10 00:31:09,505] {docker.py:308} INFO - [0m00:31:09  [33m[Errno 2] No such file or directory: '/dbtlearn/seeds/full_moon_dates.csv'[0m
[2024-07-10 00:31:09,505] {docker.py:308} INFO - [0m00:31:09
[2024-07-10 00:31:09,506] {docker.py:308} INFO - [0m00:31:09  Done. PASS=0 WARN=0 ERROR=1 SKIP=0 TOTAL=1
[2024-07-10 00:31:09,903] {taskinstance.py:1889} ERROR - Task failed with exception
Traceback (most recent call last):
  File "/home/airflow/.local/lib/python3.7/site-packages/airflow/providers/docker/operators/docker.py", line 387, in execute
    return self._run_image()
  File "/home/airflow/.local/lib/python3.7/site-packages/airflow/providers/docker/operators/docker.py", line 266, in _run_image
    return self._run_image_with_mounts(self.mounts, add_tmp_variable=False)
  File "/home/airflow/.local/lib/python3.7/site-packages/airflow/providers/docker/operators/docker.py", line 313, in _run_image_with_mounts
    raise AirflowException(f'Docker container failed: {repr(result)} lines {joined_log_lines}')
airflow.exceptions.AirflowException: Docker container failed: {'StatusCode': 1} lines [0m00:31:07  Running with dbt=1.5.0
[0m00:31:07  Found 9 models, 0 tests, 0 snapshots, 0 analyses, 321 macros, 0 operations, 1 seed file, 0 sources, 0 exposures, 0 metrics, 0 groups
[0m00:31:07
[0m00:31:09  Concurrency: 1 threads (target='dev')
[0m00:31:09
[0m00:31:09  1 of 1 START seed file DEV.full_moon_dates ..................................... [RUN]
[0m00:31:09  [31mUnhandled error while executing [0m
[Errno 2] No such file or directory: '/dbtlearn/seeds/full_moon_dates.csv'
[0m00:31:09  1 of 1 ERROR loading seed file DEV.full_moon_dates ............................. [[31mERROR[0m in 0.03s]
[0m00:31:09
[0m00:31:09  Finished running 1 seed in 0 hours 0 minutes and 1.85 seconds (1.85s).
[0m00:31:09
[0m00:31:09  [31mCompleted with 1 error and 0 warnings:[0m
[0m00:31:09
[0m00:31:09  [33m[Errno 2] No such file or directory: '/dbtlearn/seeds/full_moon_dates.csv'[0m
[0m00:31:09
[0m00:31:09  Done. PASS=0 WARN=0 ERROR=1 SKIP=0 TOTAL=1
[2024-07-10 00:31:09,908] {taskinstance.py:1400} INFO - Marking task as FAILED. dag_id=create_layers_in_snowflake, task_id=create_seeds, execution_date=20240710T003104, start_date=20240710T003105, end_date=20240710T003109
[2024-07-10 00:31:09,921] {standard_task_runner.py:97} ERROR - Failed to execute job 3 for task create_seeds (Docker container failed: {'StatusCode': 1} lines [0m00:31:07  Running with dbt=1.5.0
[0m00:31:07  Found 9 models, 0 tests, 0 snapshots, 0 analyses, 321 macros, 0 operations, 1 seed file, 0 sources, 0 exposures, 0 metrics, 0 groups
[0m00:31:07
[0m00:31:09  Concurrency: 1 threads (target='dev')
[0m00:31:09
[0m00:31:09  1 of 1 START seed file DEV.full_moon_dates ..................................... [RUN]
[0m00:31:09  [31mUnhandled error while executing [0m
[Errno 2] No such file or directory: '/dbtlearn/seeds/full_moon_dates.csv'
[0m00:31:09  1 of 1 ERROR loading seed file DEV.full_moon_dates ............................. [[31mERROR[0m in 0.03s]
[0m00:31:09
[0m00:31:09  Finished running 1 seed in 0 hours 0 minutes and 1.85 seconds (1.85s).
[0m00:31:09
[0m00:31:09  [31mCompleted with 1 error and 0 warnings:[0m
[0m00:31:09
[0m00:31:09  [33m[Errno 2] No such file or directory: '/dbtlearn/seeds/full_moon_dates.csv'[0m
[0m00:31:09
[0m00:31:09  Done. PASS=0 WARN=0 ERROR=1 SKIP=0 TOTAL=1; 201)
[2024-07-10 00:31:09,934] {local_task_job.py:156} INFO - Task exited with return code 1
[2024-07-10 00:31:09,964] {local_task_job.py:273} INFO - 0 downstream tasks scheduled from follow-on schedule check
