[2024-07-10 13:47:43,610] {taskinstance.py:1159} INFO - Dependencies all met for <TaskInstance: create_layers_in_snowflake.create_seeds manual__2024-07-10T13:47:42.584214+00:00 [queued]>
[2024-07-10 13:47:43,620] {taskinstance.py:1159} INFO - Dependencies all met for <TaskInstance: create_layers_in_snowflake.create_seeds manual__2024-07-10T13:47:42.584214+00:00 [queued]>
[2024-07-10 13:47:43,621] {taskinstance.py:1356} INFO - 
--------------------------------------------------------------------------------
[2024-07-10 13:47:43,621] {taskinstance.py:1357} INFO - Starting attempt 1 of 1
[2024-07-10 13:47:43,621] {taskinstance.py:1358} INFO - 
--------------------------------------------------------------------------------
[2024-07-10 13:47:43,635] {taskinstance.py:1377} INFO - Executing <Task(DockerOperator): create_seeds> on 2024-07-10 13:47:42.584214+00:00
[2024-07-10 13:47:43,639] {standard_task_runner.py:52} INFO - Started process 367 to run task
[2024-07-10 13:47:43,642] {standard_task_runner.py:79} INFO - Running: ['***', 'tasks', 'run', 'create_layers_in_snowflake', 'create_seeds', 'manual__2024-07-10T13:47:42.584214+00:00', '--job-id', '5', '--raw', '--subdir', 'DAGS_FOLDER/create_layers.py', '--cfg-path', '/tmp/tmpzt_ihvfv', '--error-file', '/tmp/tmp_w8bnskq']
[2024-07-10 13:47:43,643] {standard_task_runner.py:80} INFO - Job 5: Subtask create_seeds
[2024-07-10 13:47:43,697] {task_command.py:369} INFO - Running <TaskInstance: create_layers_in_snowflake.create_seeds manual__2024-07-10T13:47:42.584214+00:00 [running]> on host bc9f9d1e47b7
[2024-07-10 13:47:43,768] {taskinstance.py:1571} INFO - Exporting the following env vars:
AIRFLOW_CTX_DAG_OWNER=***
AIRFLOW_CTX_DAG_ID=create_layers_in_snowflake
AIRFLOW_CTX_TASK_ID=create_seeds
AIRFLOW_CTX_EXECUTION_DATE=2024-07-10T13:47:42.584214+00:00
AIRFLOW_CTX_TRY_NUMBER=1
AIRFLOW_CTX_DAG_RUN_ID=manual__2024-07-10T13:47:42.584214+00:00
[2024-07-10 13:47:43,790] {docker.py:247} INFO - Starting docker container from image custom_dbt_image
[2024-07-10 13:47:43,910] {taskinstance.py:1889} ERROR - Task failed with exception
Traceback (most recent call last):
  File "/home/airflow/.local/lib/python3.7/site-packages/docker/api/client.py", line 268, in _raise_for_status
    response.raise_for_status()
  File "/home/airflow/.local/lib/python3.7/site-packages/requests/models.py", line 960, in raise_for_status
    raise HTTPError(http_error_msg, response=self)
requests.exceptions.HTTPError: 400 Client Error: Bad Request for url: http+docker://localhost/v1.45/containers/9ebe37484417dfe7094e5f725e16df046a893496756b31bbcebd0d1f5d230644/start

During handling of the above exception, another exception occurred:

Traceback (most recent call last):
  File "/home/airflow/.local/lib/python3.7/site-packages/airflow/providers/docker/operators/docker.py", line 387, in execute
    return self._run_image()
  File "/home/airflow/.local/lib/python3.7/site-packages/airflow/providers/docker/operators/docker.py", line 266, in _run_image
    return self._run_image_with_mounts(self.mounts, add_tmp_variable=False)
  File "/home/airflow/.local/lib/python3.7/site-packages/airflow/providers/docker/operators/docker.py", line 302, in _run_image_with_mounts
    self.cli.start(self.container['Id'])
  File "/home/airflow/.local/lib/python3.7/site-packages/docker/utils/decorators.py", line 19, in wrapped
    return f(self, resource_id, *args, **kwargs)
  File "/home/airflow/.local/lib/python3.7/site-packages/docker/api/container.py", line 1109, in start
    self._raise_for_status(res)
  File "/home/airflow/.local/lib/python3.7/site-packages/docker/api/client.py", line 270, in _raise_for_status
    raise create_api_error_from_http_exception(e)
  File "/home/airflow/.local/lib/python3.7/site-packages/docker/errors.py", line 31, in create_api_error_from_http_exception
    raise cls(e, response=response, explanation=explanation)
docker.errors.APIError: 400 Client Error for http+docker://localhost/v1.45/containers/9ebe37484417dfe7094e5f725e16df046a893496756b31bbcebd0d1f5d230644/start: Bad Request ("failed to create task for container: failed to create shim task: OCI runtime create failed: runc create failed: unable to start container process: exec: "cd": executable file not found in $PATH: unknown")
[2024-07-10 13:47:43,921] {taskinstance.py:1400} INFO - Marking task as FAILED. dag_id=create_layers_in_snowflake, task_id=create_seeds, execution_date=20240710T134742, start_date=20240710T134743, end_date=20240710T134743
[2024-07-10 13:47:43,934] {standard_task_runner.py:97} ERROR - Failed to execute job 5 for task create_seeds (400 Client Error for http+docker://localhost/v1.45/containers/9ebe37484417dfe7094e5f725e16df046a893496756b31bbcebd0d1f5d230644/start: Bad Request ("failed to create task for container: failed to create shim task: OCI runtime create failed: runc create failed: unable to start container process: exec: "cd": executable file not found in $PATH: unknown"); 367)
[2024-07-10 13:47:43,947] {local_task_job.py:156} INFO - Task exited with return code 1
[2024-07-10 13:47:43,995] {local_task_job.py:273} INFO - 0 downstream tasks scheduled from follow-on schedule check
