[2024-07-10 14:45:09,813] {taskinstance.py:1159} INFO - Dependencies all met for <TaskInstance: create_layers_in_snowflake.create_seeds manual__2024-07-10T14:45:08.962695+00:00 [queued]>
[2024-07-10 14:45:09,822] {taskinstance.py:1159} INFO - Dependencies all met for <TaskInstance: create_layers_in_snowflake.create_seeds manual__2024-07-10T14:45:08.962695+00:00 [queued]>
[2024-07-10 14:45:09,823] {taskinstance.py:1356} INFO - 
--------------------------------------------------------------------------------
[2024-07-10 14:45:09,823] {taskinstance.py:1357} INFO - Starting attempt 1 of 1
[2024-07-10 14:45:09,824] {taskinstance.py:1358} INFO - 
--------------------------------------------------------------------------------
[2024-07-10 14:45:09,837] {taskinstance.py:1377} INFO - Executing <Task(DockerOperator): create_seeds> on 2024-07-10 14:45:08.962695+00:00
[2024-07-10 14:45:09,840] {standard_task_runner.py:52} INFO - Started process 3106 to run task
[2024-07-10 14:45:09,843] {standard_task_runner.py:79} INFO - Running: ['***', 'tasks', 'run', 'create_layers_in_snowflake', 'create_seeds', 'manual__2024-07-10T14:45:08.962695+00:00', '--job-id', '28', '--raw', '--subdir', 'DAGS_FOLDER/create_layers.py', '--cfg-path', '/tmp/tmprd349lmy', '--error-file', '/tmp/tmpeq6236wj']
[2024-07-10 14:45:09,844] {standard_task_runner.py:80} INFO - Job 28: Subtask create_seeds
[2024-07-10 14:45:09,898] {task_command.py:369} INFO - Running <TaskInstance: create_layers_in_snowflake.create_seeds manual__2024-07-10T14:45:08.962695+00:00 [running]> on host bc9f9d1e47b7
[2024-07-10 14:45:09,971] {taskinstance.py:1571} INFO - Exporting the following env vars:
AIRFLOW_CTX_DAG_OWNER=***
AIRFLOW_CTX_DAG_ID=create_layers_in_snowflake
AIRFLOW_CTX_TASK_ID=create_seeds
AIRFLOW_CTX_EXECUTION_DATE=2024-07-10T14:45:08.962695+00:00
AIRFLOW_CTX_TRY_NUMBER=1
AIRFLOW_CTX_DAG_RUN_ID=manual__2024-07-10T14:45:08.962695+00:00
[2024-07-10 14:45:09,991] {docker.py:247} INFO - Starting docker container from image custom_dbt_image
[2024-07-10 14:45:10,100] {docker.py:308} INFO - total 8
drwxr-xr-x 10 root root 4096 Jul 10 00:27 dbtlearn
-rw-r--r--  1 root root   55 Jul  9 18:41 requirements.txt
[2024-07-10 14:45:11,907] {docker.py:308} INFO - Usage: dbt seed [OPTIONS]
Try 'dbt seed -h' for help.

Error: Invalid value for '--project-dir': Path '/dbtlearn' does not exist.
[2024-07-10 14:45:12,054] {taskinstance.py:1889} ERROR - Task failed with exception
Traceback (most recent call last):
  File "/home/airflow/.local/lib/python3.7/site-packages/airflow/providers/docker/operators/docker.py", line 387, in execute
    return self._run_image()
  File "/home/airflow/.local/lib/python3.7/site-packages/airflow/providers/docker/operators/docker.py", line 266, in _run_image
    return self._run_image_with_mounts(self.mounts, add_tmp_variable=False)
  File "/home/airflow/.local/lib/python3.7/site-packages/airflow/providers/docker/operators/docker.py", line 313, in _run_image_with_mounts
    raise AirflowException(f'Docker container failed: {repr(result)} lines {joined_log_lines}')
airflow.exceptions.AirflowException: Docker container failed: {'StatusCode': 2} lines total 8
drwxr-xr-x 10 root root 4096 Jul 10 00:27 dbtlearn
-rw-r--r--  1 root root   55 Jul  9 18:41 requirements.txt
Usage: dbt seed [OPTIONS]
Try 'dbt seed -h' for help.

Error: Invalid value for '--project-dir': Path '/dbtlearn' does not exist.
[2024-07-10 14:45:12,057] {taskinstance.py:1400} INFO - Marking task as FAILED. dag_id=create_layers_in_snowflake, task_id=create_seeds, execution_date=20240710T144508, start_date=20240710T144509, end_date=20240710T144512
[2024-07-10 14:45:12,068] {standard_task_runner.py:97} ERROR - Failed to execute job 28 for task create_seeds (Docker container failed: {'StatusCode': 2} lines total 8
drwxr-xr-x 10 root root 4096 Jul 10 00:27 dbtlearn
-rw-r--r--  1 root root   55 Jul  9 18:41 requirements.txt
Usage: dbt seed [OPTIONS]
Try 'dbt seed -h' for help.

Error: Invalid value for '--project-dir': Path '/dbtlearn' does not exist.; 3106)
[2024-07-10 14:45:12,115] {local_task_job.py:156} INFO - Task exited with return code 1
[2024-07-10 14:45:12,193] {local_task_job.py:273} INFO - 0 downstream tasks scheduled from follow-on schedule check
