[2024-07-10 14:32:27,796] {taskinstance.py:1159} INFO - Dependencies all met for <TaskInstance: create_layers_in_snowflake.create_seeds manual__2024-07-10T14:32:26.771890+00:00 [queued]>
[2024-07-10 14:32:27,807] {taskinstance.py:1159} INFO - Dependencies all met for <TaskInstance: create_layers_in_snowflake.create_seeds manual__2024-07-10T14:32:26.771890+00:00 [queued]>
[2024-07-10 14:32:27,807] {taskinstance.py:1356} INFO - 
--------------------------------------------------------------------------------
[2024-07-10 14:32:27,808] {taskinstance.py:1357} INFO - Starting attempt 1 of 1
[2024-07-10 14:32:27,808] {taskinstance.py:1358} INFO - 
--------------------------------------------------------------------------------
[2024-07-10 14:32:27,822] {taskinstance.py:1377} INFO - Executing <Task(DockerOperator): create_seeds> on 2024-07-10 14:32:26.771890+00:00
[2024-07-10 14:32:27,826] {standard_task_runner.py:52} INFO - Started process 2507 to run task
[2024-07-10 14:32:27,829] {standard_task_runner.py:79} INFO - Running: ['***', 'tasks', 'run', 'create_layers_in_snowflake', 'create_seeds', 'manual__2024-07-10T14:32:26.771890+00:00', '--job-id', '24', '--raw', '--subdir', 'DAGS_FOLDER/create_layers.py', '--cfg-path', '/tmp/tmp56hz2p9s', '--error-file', '/tmp/tmp1hlqkea4']
[2024-07-10 14:32:27,830] {standard_task_runner.py:80} INFO - Job 24: Subtask create_seeds
[2024-07-10 14:32:27,885] {task_command.py:369} INFO - Running <TaskInstance: create_layers_in_snowflake.create_seeds manual__2024-07-10T14:32:26.771890+00:00 [running]> on host bc9f9d1e47b7
[2024-07-10 14:32:27,960] {taskinstance.py:1571} INFO - Exporting the following env vars:
AIRFLOW_CTX_DAG_OWNER=***
AIRFLOW_CTX_DAG_ID=create_layers_in_snowflake
AIRFLOW_CTX_TASK_ID=create_seeds
AIRFLOW_CTX_EXECUTION_DATE=2024-07-10T14:32:26.771890+00:00
AIRFLOW_CTX_TRY_NUMBER=1
AIRFLOW_CTX_DAG_RUN_ID=manual__2024-07-10T14:32:26.771890+00:00
[2024-07-10 14:32:27,987] {docker.py:247} INFO - Starting docker container from image custom_dbt_image
[2024-07-10 14:32:28,092] {docker.py:308} INFO - total 8
drwxr-xr-x 10 root root 4096 Jul 10 00:27 dbtlearn
-rw-r--r--  1 root root   55 Jul  9 18:41 requirements.txt
[2024-07-10 14:32:28,196] {docker.py:308} INFO - total 12
drwxr-xr-x 1 root root 4096 Jul 10 00:27 dbtlearn
-rw-r--r-- 1 root root   55 Jul  9 18:41 requirements.txt
[2024-07-10 14:32:28,198] {docker.py:308} INFO - total 72
-rwxr-xr-x 1 root root  571 Jul 10 00:27 README.md
drwxr-xr-x 1 root root 4096 Jul 10 00:27 dbt_packages
-rwxr-xr-x 1 root root 1237 Jul 10 00:27 dbt_project.yml
drwxr-xr-x 1 root root 4096 Jul 10 00:27 logs
drwxr-xr-x 1 root root 4096 Jul 10 00:27 macros
drwxr-xr-x 1 root root 4096 Jul 10 00:27 models
-rwxr-xr-x 1 root root  255 Jul 10 00:27 profiles.yml
drwxr-xr-x 1 root root 4096 Jul 10 00:27 seeds
drwxr-xr-x 1 root root 4096 Jul 10 00:27 snapshots
drwxr-xr-x 1 root root 4096 Jul 10 00:27 target
drwxr-xr-x 1 root root 4096 Jul 10 00:27 tests
[2024-07-10 14:32:28,199] {docker.py:308} INFO - total 4
-rwxr-xr-x 1 root root 3007 Jul 10 00:27 full_moon_dates.csv
[2024-07-10 14:32:30,135] {docker.py:308} INFO - [0m14:32:30  Running with dbt=1.5.0
[2024-07-10 14:32:30,472] {docker.py:308} INFO - [0m14:32:30  Found 9 models, 0 tests, 0 snapshots, 0 analyses, 321 macros, 0 operations, 1 seed file, 0 sources, 0 exposures, 0 metrics, 0 groups
[2024-07-10 14:32:30,474] {docker.py:308} INFO - [0m14:32:30
[2024-07-10 14:32:32,113] {docker.py:308} INFO - [0m14:32:32  Concurrency: 1 threads (target='dev')
[2024-07-10 14:32:32,114] {docker.py:308} INFO - [0m14:32:32
[2024-07-10 14:32:32,117] {docker.py:308} INFO - [0m14:32:32  1 of 1 START seed file DEV.full_moon_dates ..................................... [RUN]
[2024-07-10 14:32:32,148] {docker.py:308} INFO - [0m14:32:32  [31mUnhandled error while executing [0m
[Errno 2] No such file or directory: '/dbtlearn/seeds/full_moon_dates.csv'
[2024-07-10 14:32:32,150] {docker.py:308} INFO - [0m14:32:32  1 of 1 ERROR loading seed file DEV.full_moon_dates ............................. [[31mERROR[0m in 0.03s]
[2024-07-10 14:32:32,219] {docker.py:308} INFO - [0m14:32:32
[2024-07-10 14:32:32,220] {docker.py:308} INFO - [0m14:32:32  Finished running 1 seed in 0 hours 0 minutes and 1.74 seconds (1.74s).
[2024-07-10 14:32:32,228] {docker.py:308} INFO - [0m14:32:32
[2024-07-10 14:32:32,228] {docker.py:308} INFO - [0m14:32:32  [31mCompleted with 1 error and 0 warnings:[0m
[2024-07-10 14:32:32,229] {docker.py:308} INFO - [0m14:32:32
[2024-07-10 14:32:32,229] {docker.py:308} INFO - [0m14:32:32  [33m[Errno 2] No such file or directory: '/dbtlearn/seeds/full_moon_dates.csv'[0m
[2024-07-10 14:32:32,230] {docker.py:308} INFO - [0m14:32:32
[2024-07-10 14:32:32,230] {docker.py:308} INFO - [0m14:32:32  Done. PASS=0 WARN=0 ERROR=1 SKIP=0 TOTAL=1
[2024-07-10 14:32:32,693] {taskinstance.py:1889} ERROR - Task failed with exception
Traceback (most recent call last):
  File "/home/airflow/.local/lib/python3.7/site-packages/airflow/providers/docker/operators/docker.py", line 387, in execute
    return self._run_image()
  File "/home/airflow/.local/lib/python3.7/site-packages/airflow/providers/docker/operators/docker.py", line 266, in _run_image
    return self._run_image_with_mounts(self.mounts, add_tmp_variable=False)
  File "/home/airflow/.local/lib/python3.7/site-packages/airflow/providers/docker/operators/docker.py", line 313, in _run_image_with_mounts
    raise AirflowException(f'Docker container failed: {repr(result)} lines {joined_log_lines}')
airflow.exceptions.AirflowException: Docker container failed: {'StatusCode': 1} lines total 8
drwxr-xr-x 10 root root 4096 Jul 10 00:27 dbtlearn
-rw-r--r--  1 root root   55 Jul  9 18:41 requirements.txt
total 12
drwxr-xr-x 1 root root 4096 Jul 10 00:27 dbtlearn
-rw-r--r-- 1 root root   55 Jul  9 18:41 requirements.txt
total 72
-rwxr-xr-x 1 root root  571 Jul 10 00:27 README.md
drwxr-xr-x 1 root root 4096 Jul 10 00:27 dbt_packages
-rwxr-xr-x 1 root root 1237 Jul 10 00:27 dbt_project.yml
drwxr-xr-x 1 root root 4096 Jul 10 00:27 logs
drwxr-xr-x 1 root root 4096 Jul 10 00:27 macros
drwxr-xr-x 1 root root 4096 Jul 10 00:27 models
-rwxr-xr-x 1 root root  255 Jul 10 00:27 profiles.yml
drwxr-xr-x 1 root root 4096 Jul 10 00:27 seeds
drwxr-xr-x 1 root root 4096 Jul 10 00:27 snapshots
drwxr-xr-x 1 root root 4096 Jul 10 00:27 target
drwxr-xr-x 1 root root 4096 Jul 10 00:27 tests
total 4
-rwxr-xr-x 1 root root 3007 Jul 10 00:27 full_moon_dates.csv
[0m14:32:30  Running with dbt=1.5.0
[0m14:32:30  Found 9 models, 0 tests, 0 snapshots, 0 analyses, 321 macros, 0 operations, 1 seed file, 0 sources, 0 exposures, 0 metrics, 0 groups
[0m14:32:30
[0m14:32:32  Concurrency: 1 threads (target='dev')
[0m14:32:32
[0m14:32:32  1 of 1 START seed file DEV.full_moon_dates ..................................... [RUN]
[0m14:32:32  [31mUnhandled error while executing [0m
[Errno 2] No such file or directory: '/dbtlearn/seeds/full_moon_dates.csv'
[0m14:32:32  1 of 1 ERROR loading seed file DEV.full_moon_dates ............................. [[31mERROR[0m in 0.03s]
[0m14:32:32
[0m14:32:32  Finished running 1 seed in 0 hours 0 minutes and 1.74 seconds (1.74s).
[0m14:32:32
[0m14:32:32  [31mCompleted with 1 error and 0 warnings:[0m
[0m14:32:32
[0m14:32:32  [33m[Errno 2] No such file or directory: '/dbtlearn/seeds/full_moon_dates.csv'[0m
[0m14:32:32
[0m14:32:32  Done. PASS=0 WARN=0 ERROR=1 SKIP=0 TOTAL=1
[2024-07-10 14:32:32,697] {taskinstance.py:1400} INFO - Marking task as FAILED. dag_id=create_layers_in_snowflake, task_id=create_seeds, execution_date=20240710T143226, start_date=20240710T143227, end_date=20240710T143232
[2024-07-10 14:32:32,708] {standard_task_runner.py:97} ERROR - Failed to execute job 24 for task create_seeds (Docker container failed: {'StatusCode': 1} lines total 8
drwxr-xr-x 10 root root 4096 Jul 10 00:27 dbtlearn
-rw-r--r--  1 root root   55 Jul  9 18:41 requirements.txt
total 12
drwxr-xr-x 1 root root 4096 Jul 10 00:27 dbtlearn
-rw-r--r-- 1 root root   55 Jul  9 18:41 requirements.txt
total 72
-rwxr-xr-x 1 root root  571 Jul 10 00:27 README.md
drwxr-xr-x 1 root root 4096 Jul 10 00:27 dbt_packages
-rwxr-xr-x 1 root root 1237 Jul 10 00:27 dbt_project.yml
drwxr-xr-x 1 root root 4096 Jul 10 00:27 logs
drwxr-xr-x 1 root root 4096 Jul 10 00:27 macros
drwxr-xr-x 1 root root 4096 Jul 10 00:27 models
-rwxr-xr-x 1 root root  255 Jul 10 00:27 profiles.yml
drwxr-xr-x 1 root root 4096 Jul 10 00:27 seeds
drwxr-xr-x 1 root root 4096 Jul 10 00:27 snapshots
drwxr-xr-x 1 root root 4096 Jul 10 00:27 target
drwxr-xr-x 1 root root 4096 Jul 10 00:27 tests
total 4
-rwxr-xr-x 1 root root 3007 Jul 10 00:27 full_moon_dates.csv
[0m14:32:30  Running with dbt=1.5.0
[0m14:32:30  Found 9 models, 0 tests, 0 snapshots, 0 analyses, 321 macros, 0 operations, 1 seed file, 0 sources, 0 exposures, 0 metrics, 0 groups
[0m14:32:30
[0m14:32:32  Concurrency: 1 threads (target='dev')
[0m14:32:32
[0m14:32:32  1 of 1 START seed file DEV.full_moon_dates ..................................... [RUN]
[0m14:32:32  [31mUnhandled error while executing [0m
[Errno 2] No such file or directory: '/dbtlearn/seeds/full_moon_dates.csv'
[0m14:32:32  1 of 1 ERROR loading seed file DEV.full_moon_dates ............................. [[31mERROR[0m in 0.03s]
[0m14:32:32
[0m14:32:32  Finished running 1 seed in 0 hours 0 minutes and 1.74 seconds (1.74s).
[0m14:32:32
[0m14:32:32  [31mCompleted with 1 error and 0 warnings:[0m
[0m14:32:32
[0m14:32:32  [33m[Errno 2] No such file or directory: '/dbtlearn/seeds/full_moon_dates.csv'[0m
[0m14:32:32
[0m14:32:32  Done. PASS=0 WARN=0 ERROR=1 SKIP=0 TOTAL=1; 2507)
[2024-07-10 14:32:32,740] {local_task_job.py:156} INFO - Task exited with return code 1
[2024-07-10 14:32:32,786] {local_task_job.py:273} INFO - 0 downstream tasks scheduled from follow-on schedule check
