[2024-07-10 00:18:20,990] {taskinstance.py:1159} INFO - Dependencies all met for <TaskInstance: create_layers_in_snowflake.create_seeds manual__2024-07-10T00:18:20.077806+00:00 [queued]>
[2024-07-10 00:18:20,999] {taskinstance.py:1159} INFO - Dependencies all met for <TaskInstance: create_layers_in_snowflake.create_seeds manual__2024-07-10T00:18:20.077806+00:00 [queued]>
[2024-07-10 00:18:21,000] {taskinstance.py:1356} INFO - 
--------------------------------------------------------------------------------
[2024-07-10 00:18:21,000] {taskinstance.py:1357} INFO - Starting attempt 1 of 1
[2024-07-10 00:18:21,000] {taskinstance.py:1358} INFO - 
--------------------------------------------------------------------------------
[2024-07-10 00:18:21,013] {taskinstance.py:1377} INFO - Executing <Task(DockerOperator): create_seeds> on 2024-07-10 00:18:20.077806+00:00
[2024-07-10 00:18:21,017] {standard_task_runner.py:52} INFO - Started process 2710 to run task
[2024-07-10 00:18:21,020] {standard_task_runner.py:79} INFO - Running: ['***', 'tasks', 'run', 'create_layers_in_snowflake', 'create_seeds', 'manual__2024-07-10T00:18:20.077806+00:00', '--job-id', '31', '--raw', '--subdir', 'DAGS_FOLDER/create_layers.py', '--cfg-path', '/tmp/tmpbuf8dj11', '--error-file', '/tmp/tmp5gdy1vu6']
[2024-07-10 00:18:21,021] {standard_task_runner.py:80} INFO - Job 31: Subtask create_seeds
[2024-07-10 00:18:21,076] {task_command.py:369} INFO - Running <TaskInstance: create_layers_in_snowflake.create_seeds manual__2024-07-10T00:18:20.077806+00:00 [running]> on host a22086a40575
[2024-07-10 00:18:21,201] {taskinstance.py:1571} INFO - Exporting the following env vars:
AIRFLOW_CTX_DAG_OWNER=***
AIRFLOW_CTX_DAG_ID=create_layers_in_snowflake
AIRFLOW_CTX_TASK_ID=create_seeds
AIRFLOW_CTX_EXECUTION_DATE=2024-07-10T00:18:20.077806+00:00
AIRFLOW_CTX_TRY_NUMBER=1
AIRFLOW_CTX_DAG_RUN_ID=manual__2024-07-10T00:18:20.077806+00:00
[2024-07-10 00:18:21,224] {docker.py:247} INFO - Starting docker container from image custom_dbt_image
[2024-07-10 00:18:21,232] {taskinstance.py:1889} ERROR - Task failed with exception
Traceback (most recent call last):
  File "/home/airflow/.local/lib/python3.7/site-packages/docker/api/client.py", line 268, in _raise_for_status
    response.raise_for_status()
  File "/home/airflow/.local/lib/python3.7/site-packages/requests/models.py", line 960, in raise_for_status
    raise HTTPError(http_error_msg, response=self)
requests.exceptions.HTTPError: 400 Client Error: Bad Request for url: http+docker://localhost/v1.45/containers/create

During handling of the above exception, another exception occurred:

Traceback (most recent call last):
  File "/home/airflow/.local/lib/python3.7/site-packages/airflow/providers/docker/operators/docker.py", line 387, in execute
    return self._run_image()
  File "/home/airflow/.local/lib/python3.7/site-packages/airflow/providers/docker/operators/docker.py", line 266, in _run_image
    return self._run_image_with_mounts(self.mounts, add_tmp_variable=False)
  File "/home/airflow/.local/lib/python3.7/site-packages/airflow/providers/docker/operators/docker.py", line 298, in _run_image_with_mounts
    tty=self.tty,
  File "/home/airflow/.local/lib/python3.7/site-packages/docker/api/container.py", line 428, in create_container
    return self.create_container_from_config(config, name)
  File "/home/airflow/.local/lib/python3.7/site-packages/docker/api/container.py", line 439, in create_container_from_config
    return self._result(res, True)
  File "/home/airflow/.local/lib/python3.7/site-packages/docker/api/client.py", line 274, in _result
    self._raise_for_status(response)
  File "/home/airflow/.local/lib/python3.7/site-packages/docker/api/client.py", line 270, in _raise_for_status
    raise create_api_error_from_http_exception(e)
  File "/home/airflow/.local/lib/python3.7/site-packages/docker/errors.py", line 31, in create_api_error_from_http_exception
    raise cls(e, response=response, explanation=explanation)
docker.errors.APIError: 400 Client Error for http+docker://localhost/v1.45/containers/create: Bad Request ("invalid mount config for type "bind": invalid mount path: 'Users/sparsons/Desktop/interview_test/Airflow_DBT_Snowflake_Docker/dbtlearn' mount path must be absolute")
[2024-07-10 00:18:21,242] {taskinstance.py:1400} INFO - Marking task as FAILED. dag_id=create_layers_in_snowflake, task_id=create_seeds, execution_date=20240710T001820, start_date=20240710T001820, end_date=20240710T001821
[2024-07-10 00:18:21,253] {standard_task_runner.py:97} ERROR - Failed to execute job 31 for task create_seeds (400 Client Error for http+docker://localhost/v1.45/containers/create: Bad Request ("invalid mount config for type "bind": invalid mount path: 'Users/sparsons/Desktop/interview_test/Airflow_DBT_Snowflake_Docker/dbtlearn' mount path must be absolute"); 2710)
[2024-07-10 00:18:21,263] {local_task_job.py:156} INFO - Task exited with return code 1
[2024-07-10 00:18:21,298] {local_task_job.py:273} INFO - 0 downstream tasks scheduled from follow-on schedule check
