[2024-07-10 14:46:33,731] {taskinstance.py:1159} INFO - Dependencies all met for <TaskInstance: create_layers_in_snowflake.create_seeds manual__2024-07-10T14:46:32.899419+00:00 [queued]>
[2024-07-10 14:46:33,741] {taskinstance.py:1159} INFO - Dependencies all met for <TaskInstance: create_layers_in_snowflake.create_seeds manual__2024-07-10T14:46:32.899419+00:00 [queued]>
[2024-07-10 14:46:33,741] {taskinstance.py:1356} INFO - 
--------------------------------------------------------------------------------
[2024-07-10 14:46:33,741] {taskinstance.py:1357} INFO - Starting attempt 1 of 1
[2024-07-10 14:46:33,742] {taskinstance.py:1358} INFO - 
--------------------------------------------------------------------------------
[2024-07-10 14:46:33,754] {taskinstance.py:1377} INFO - Executing <Task(DockerOperator): create_seeds> on 2024-07-10 14:46:32.899419+00:00
[2024-07-10 14:46:33,758] {standard_task_runner.py:52} INFO - Started process 3182 to run task
[2024-07-10 14:46:33,761] {standard_task_runner.py:79} INFO - Running: ['***', 'tasks', 'run', 'create_layers_in_snowflake', 'create_seeds', 'manual__2024-07-10T14:46:32.899419+00:00', '--job-id', '30', '--raw', '--subdir', 'DAGS_FOLDER/create_layers.py', '--cfg-path', '/tmp/tmpq41i5894', '--error-file', '/tmp/tmpdfootmpz']
[2024-07-10 14:46:33,762] {standard_task_runner.py:80} INFO - Job 30: Subtask create_seeds
[2024-07-10 14:46:33,816] {task_command.py:369} INFO - Running <TaskInstance: create_layers_in_snowflake.create_seeds manual__2024-07-10T14:46:32.899419+00:00 [running]> on host bc9f9d1e47b7
[2024-07-10 14:46:33,893] {taskinstance.py:1571} INFO - Exporting the following env vars:
AIRFLOW_CTX_DAG_OWNER=***
AIRFLOW_CTX_DAG_ID=create_layers_in_snowflake
AIRFLOW_CTX_TASK_ID=create_seeds
AIRFLOW_CTX_EXECUTION_DATE=2024-07-10T14:46:32.899419+00:00
AIRFLOW_CTX_TRY_NUMBER=1
AIRFLOW_CTX_DAG_RUN_ID=manual__2024-07-10T14:46:32.899419+00:00
[2024-07-10 14:46:33,914] {docker.py:247} INFO - Starting docker container from image custom_dbt_image
[2024-07-10 14:46:34,028] {docker.py:308} INFO - total 8
drwxr-xr-x 10 root root 4096 Jul 10 00:27 dbtlearn
-rw-r--r--  1 root root   55 Jul  9 18:41 requirements.txt
[2024-07-10 14:46:35,831] {docker.py:308} INFO - [0m14:46:35  Running with dbt=1.5.0
[2024-07-10 14:46:36,194] {docker.py:308} INFO - [0m14:46:36  Found 9 models, 0 tests, 0 snapshots, 0 analyses, 321 macros, 0 operations, 1 seed file, 0 sources, 0 exposures, 0 metrics, 0 groups
[2024-07-10 14:46:36,195] {docker.py:308} INFO - [0m14:46:36
[2024-07-10 14:46:38,030] {docker.py:308} INFO - [0m14:46:38  Concurrency: 1 threads (target='dev')
[2024-07-10 14:46:38,031] {docker.py:308} INFO - [0m14:46:38
[2024-07-10 14:46:38,034] {docker.py:308} INFO - [0m14:46:38  1 of 1 START seed file DEV.full_moon_dates ..................................... [RUN]
[2024-07-10 14:46:38,062] {docker.py:308} INFO - [0m14:46:38  [31mUnhandled error while executing [0m
[Errno 2] No such file or directory: '/dbtlearn/seeds/full_moon_dates.csv'
[2024-07-10 14:46:38,064] {docker.py:308} INFO - [0m14:46:38  1 of 1 ERROR loading seed file DEV.full_moon_dates ............................. [[31mERROR[0m in 0.03s]
[2024-07-10 14:46:38,136] {docker.py:308} INFO - [0m14:46:38
[2024-07-10 14:46:38,136] {docker.py:308} INFO - [0m14:46:38  Finished running 1 seed in 0 hours 0 minutes and 1.94 seconds (1.94s).
[2024-07-10 14:46:38,147] {docker.py:308} INFO - [0m14:46:38
[2024-07-10 14:46:38,148] {docker.py:308} INFO - [0m14:46:38  [31mCompleted with 1 error and 0 warnings:[0m
[2024-07-10 14:46:38,148] {docker.py:308} INFO - [0m14:46:38
[2024-07-10 14:46:38,149] {docker.py:308} INFO - [0m14:46:38  [33m[Errno 2] No such file or directory: '/dbtlearn/seeds/full_moon_dates.csv'[0m
[2024-07-10 14:46:38,150] {docker.py:308} INFO - [0m14:46:38
[2024-07-10 14:46:38,150] {docker.py:308} INFO - [0m14:46:38  Done. PASS=0 WARN=0 ERROR=1 SKIP=0 TOTAL=1
[2024-07-10 14:46:38,477] {taskinstance.py:1889} ERROR - Task failed with exception
Traceback (most recent call last):
  File "/home/airflow/.local/lib/python3.7/site-packages/airflow/providers/docker/operators/docker.py", line 387, in execute
    return self._run_image()
  File "/home/airflow/.local/lib/python3.7/site-packages/airflow/providers/docker/operators/docker.py", line 266, in _run_image
    return self._run_image_with_mounts(self.mounts, add_tmp_variable=False)
  File "/home/airflow/.local/lib/python3.7/site-packages/airflow/providers/docker/operators/docker.py", line 313, in _run_image_with_mounts
    raise AirflowException(f'Docker container failed: {repr(result)} lines {joined_log_lines}')
airflow.exceptions.AirflowException: Docker container failed: {'StatusCode': 1} lines total 8
drwxr-xr-x 10 root root 4096 Jul 10 00:27 dbtlearn
-rw-r--r--  1 root root   55 Jul  9 18:41 requirements.txt
[0m14:46:35  Running with dbt=1.5.0
[0m14:46:36  Found 9 models, 0 tests, 0 snapshots, 0 analyses, 321 macros, 0 operations, 1 seed file, 0 sources, 0 exposures, 0 metrics, 0 groups
[0m14:46:36
[0m14:46:38  Concurrency: 1 threads (target='dev')
[0m14:46:38
[0m14:46:38  1 of 1 START seed file DEV.full_moon_dates ..................................... [RUN]
[0m14:46:38  [31mUnhandled error while executing [0m
[Errno 2] No such file or directory: '/dbtlearn/seeds/full_moon_dates.csv'
[0m14:46:38  1 of 1 ERROR loading seed file DEV.full_moon_dates ............................. [[31mERROR[0m in 0.03s]
[0m14:46:38
[0m14:46:38  Finished running 1 seed in 0 hours 0 minutes and 1.94 seconds (1.94s).
[0m14:46:38
[0m14:46:38  [31mCompleted with 1 error and 0 warnings:[0m
[0m14:46:38
[0m14:46:38  [33m[Errno 2] No such file or directory: '/dbtlearn/seeds/full_moon_dates.csv'[0m
[0m14:46:38
[0m14:46:38  Done. PASS=0 WARN=0 ERROR=1 SKIP=0 TOTAL=1
[2024-07-10 14:46:38,480] {taskinstance.py:1400} INFO - Marking task as FAILED. dag_id=create_layers_in_snowflake, task_id=create_seeds, execution_date=20240710T144632, start_date=20240710T144633, end_date=20240710T144638
[2024-07-10 14:46:38,494] {standard_task_runner.py:97} ERROR - Failed to execute job 30 for task create_seeds (Docker container failed: {'StatusCode': 1} lines total 8
drwxr-xr-x 10 root root 4096 Jul 10 00:27 dbtlearn
-rw-r--r--  1 root root   55 Jul  9 18:41 requirements.txt
[0m14:46:35  Running with dbt=1.5.0
[0m14:46:36  Found 9 models, 0 tests, 0 snapshots, 0 analyses, 321 macros, 0 operations, 1 seed file, 0 sources, 0 exposures, 0 metrics, 0 groups
[0m14:46:36
[0m14:46:38  Concurrency: 1 threads (target='dev')
[0m14:46:38
[0m14:46:38  1 of 1 START seed file DEV.full_moon_dates ..................................... [RUN]
[0m14:46:38  [31mUnhandled error while executing [0m
[Errno 2] No such file or directory: '/dbtlearn/seeds/full_moon_dates.csv'
[0m14:46:38  1 of 1 ERROR loading seed file DEV.full_moon_dates ............................. [[31mERROR[0m in 0.03s]
[0m14:46:38
[0m14:46:38  Finished running 1 seed in 0 hours 0 minutes and 1.94 seconds (1.94s).
[0m14:46:38
[0m14:46:38  [31mCompleted with 1 error and 0 warnings:[0m
[0m14:46:38
[0m14:46:38  [33m[Errno 2] No such file or directory: '/dbtlearn/seeds/full_moon_dates.csv'[0m
[0m14:46:38
[0m14:46:38  Done. PASS=0 WARN=0 ERROR=1 SKIP=0 TOTAL=1; 3182)
[2024-07-10 14:46:38,511] {local_task_job.py:156} INFO - Task exited with return code 1
[2024-07-10 14:46:38,553] {local_task_job.py:273} INFO - 0 downstream tasks scheduled from follow-on schedule check
