[2024-07-10 14:38:43,323] {taskinstance.py:1159} INFO - Dependencies all met for <TaskInstance: create_layers_in_snowflake.create_seeds manual__2024-07-10T14:38:42.576998+00:00 [queued]>
[2024-07-10 14:38:43,331] {taskinstance.py:1159} INFO - Dependencies all met for <TaskInstance: create_layers_in_snowflake.create_seeds manual__2024-07-10T14:38:42.576998+00:00 [queued]>
[2024-07-10 14:38:43,331] {taskinstance.py:1356} INFO - 
--------------------------------------------------------------------------------
[2024-07-10 14:38:43,331] {taskinstance.py:1357} INFO - Starting attempt 1 of 1
[2024-07-10 14:38:43,332] {taskinstance.py:1358} INFO - 
--------------------------------------------------------------------------------
[2024-07-10 14:38:43,343] {taskinstance.py:1377} INFO - Executing <Task(DockerOperator): create_seeds> on 2024-07-10 14:38:42.576998+00:00
[2024-07-10 14:38:43,346] {standard_task_runner.py:52} INFO - Started process 2806 to run task
[2024-07-10 14:38:43,349] {standard_task_runner.py:79} INFO - Running: ['***', 'tasks', 'run', 'create_layers_in_snowflake', 'create_seeds', 'manual__2024-07-10T14:38:42.576998+00:00', '--job-id', '26', '--raw', '--subdir', 'DAGS_FOLDER/create_layers.py', '--cfg-path', '/tmp/tmp6rhhpp_m', '--error-file', '/tmp/tmp2bcqk3pk']
[2024-07-10 14:38:43,349] {standard_task_runner.py:80} INFO - Job 26: Subtask create_seeds
[2024-07-10 14:38:43,401] {task_command.py:369} INFO - Running <TaskInstance: create_layers_in_snowflake.create_seeds manual__2024-07-10T14:38:42.576998+00:00 [running]> on host bc9f9d1e47b7
[2024-07-10 14:38:43,461] {taskinstance.py:1571} INFO - Exporting the following env vars:
AIRFLOW_CTX_DAG_OWNER=***
AIRFLOW_CTX_DAG_ID=create_layers_in_snowflake
AIRFLOW_CTX_TASK_ID=create_seeds
AIRFLOW_CTX_EXECUTION_DATE=2024-07-10T14:38:42.576998+00:00
AIRFLOW_CTX_TRY_NUMBER=1
AIRFLOW_CTX_DAG_RUN_ID=manual__2024-07-10T14:38:42.576998+00:00
[2024-07-10 14:38:43,484] {docker.py:247} INFO - Starting docker container from image custom_dbt_image
[2024-07-10 14:38:43,593] {docker.py:308} INFO - total 8
drwxr-xr-x 10 root root 4096 Jul 10 00:27 dbtlearn
-rw-r--r--  1 root root   55 Jul  9 18:41 requirements.txt
[2024-07-10 14:38:43,699] {docker.py:308} INFO - total 12
drwxrwxrwx 1 root root 4096 Jul 10 00:27 dbtlearn
-rw-r--r-- 1 root root   55 Jul  9 18:41 requirements.txt
[2024-07-10 14:38:43,701] {docker.py:308} INFO - total 72
-rwxrwxrwx 1 root root  571 Jul 10 00:27 README.md
drwxrwxrwx 1 root root 4096 Jul 10 00:27 dbt_packages
-rwxrwxrwx 1 root root 1237 Jul 10 00:27 dbt_project.yml
drwxrwxrwx 1 root root 4096 Jul 10 00:27 logs
drwxrwxrwx 1 root root 4096 Jul 10 00:27 macros
drwxrwxrwx 1 root root 4096 Jul 10 00:27 models
-rwxrwxrwx 1 root root  255 Jul 10 00:27 profiles.yml
drwxrwxrwx 1 root root 4096 Jul 10 00:27 seeds
drwxrwxrwx 1 root root 4096 Jul 10 00:27 snapshots
drwxrwxrwx 1 root root 4096 Jul 10 00:27 target
drwxrwxrwx 1 root root 4096 Jul 10 00:27 tests
[2024-07-10 14:38:43,703] {docker.py:308} INFO - total 4
-rwxrwxrwx 1 root root 3007 Jul 10 00:27 full_moon_dates.csv
[2024-07-10 14:38:45,490] {docker.py:308} INFO - [0m14:38:45  Running with dbt=1.5.0
[2024-07-10 14:38:45,853] {docker.py:308} INFO - [0m14:38:45  Found 9 models, 0 tests, 0 snapshots, 0 analyses, 321 macros, 0 operations, 1 seed file, 0 sources, 0 exposures, 0 metrics, 0 groups
[2024-07-10 14:38:45,855] {docker.py:308} INFO - [0m14:38:45
[2024-07-10 14:38:48,071] {docker.py:308} INFO - [0m14:38:48  Concurrency: 1 threads (target='dev')
[2024-07-10 14:38:48,072] {docker.py:308} INFO - [0m14:38:48
[2024-07-10 14:38:48,075] {docker.py:308} INFO - [0m14:38:48  1 of 1 START seed file DEV.full_moon_dates ..................................... [RUN]
[2024-07-10 14:38:48,108] {docker.py:308} INFO - [0m14:38:48  [31mUnhandled error while executing [0m
[Errno 2] No such file or directory: '/dbtlearn/seeds/full_moon_dates.csv'
[2024-07-10 14:38:48,111] {docker.py:308} INFO - [0m14:38:48  1 of 1 ERROR loading seed file DEV.full_moon_dates ............................. [[31mERROR[0m in 0.03s]
[2024-07-10 14:38:48,177] {docker.py:308} INFO - [0m14:38:48
[2024-07-10 14:38:48,179] {docker.py:308} INFO - [0m14:38:48  Finished running 1 seed in 0 hours 0 minutes and 2.32 seconds (2.32s).
[2024-07-10 14:38:48,186] {docker.py:308} INFO - [0m14:38:48
[2024-07-10 14:38:48,186] {docker.py:308} INFO - [0m14:38:48  [31mCompleted with 1 error and 0 warnings:[0m
[2024-07-10 14:38:48,187] {docker.py:308} INFO - [0m14:38:48
[2024-07-10 14:38:48,187] {docker.py:308} INFO - [0m14:38:48  [33m[Errno 2] No such file or directory: '/dbtlearn/seeds/full_moon_dates.csv'[0m
[2024-07-10 14:38:48,188] {docker.py:308} INFO - [0m14:38:48
[2024-07-10 14:38:48,188] {docker.py:308} INFO - [0m14:38:48  Done. PASS=0 WARN=0 ERROR=1 SKIP=0 TOTAL=1
[2024-07-10 14:38:48,986] {taskinstance.py:1889} ERROR - Task failed with exception
Traceback (most recent call last):
  File "/home/airflow/.local/lib/python3.7/site-packages/airflow/providers/docker/operators/docker.py", line 387, in execute
    return self._run_image()
  File "/home/airflow/.local/lib/python3.7/site-packages/airflow/providers/docker/operators/docker.py", line 266, in _run_image
    return self._run_image_with_mounts(self.mounts, add_tmp_variable=False)
  File "/home/airflow/.local/lib/python3.7/site-packages/airflow/providers/docker/operators/docker.py", line 313, in _run_image_with_mounts
    raise AirflowException(f'Docker container failed: {repr(result)} lines {joined_log_lines}')
airflow.exceptions.AirflowException: Docker container failed: {'StatusCode': 1} lines total 8
drwxr-xr-x 10 root root 4096 Jul 10 00:27 dbtlearn
-rw-r--r--  1 root root   55 Jul  9 18:41 requirements.txt
total 12
drwxrwxrwx 1 root root 4096 Jul 10 00:27 dbtlearn
-rw-r--r-- 1 root root   55 Jul  9 18:41 requirements.txt
total 72
-rwxrwxrwx 1 root root  571 Jul 10 00:27 README.md
drwxrwxrwx 1 root root 4096 Jul 10 00:27 dbt_packages
-rwxrwxrwx 1 root root 1237 Jul 10 00:27 dbt_project.yml
drwxrwxrwx 1 root root 4096 Jul 10 00:27 logs
drwxrwxrwx 1 root root 4096 Jul 10 00:27 macros
drwxrwxrwx 1 root root 4096 Jul 10 00:27 models
-rwxrwxrwx 1 root root  255 Jul 10 00:27 profiles.yml
drwxrwxrwx 1 root root 4096 Jul 10 00:27 seeds
drwxrwxrwx 1 root root 4096 Jul 10 00:27 snapshots
drwxrwxrwx 1 root root 4096 Jul 10 00:27 target
drwxrwxrwx 1 root root 4096 Jul 10 00:27 tests
total 4
-rwxrwxrwx 1 root root 3007 Jul 10 00:27 full_moon_dates.csv
[0m14:38:45  Running with dbt=1.5.0
[0m14:38:45  Found 9 models, 0 tests, 0 snapshots, 0 analyses, 321 macros, 0 operations, 1 seed file, 0 sources, 0 exposures, 0 metrics, 0 groups
[0m14:38:45
[0m14:38:48  Concurrency: 1 threads (target='dev')
[0m14:38:48
[0m14:38:48  1 of 1 START seed file DEV.full_moon_dates ..................................... [RUN]
[0m14:38:48  [31mUnhandled error while executing [0m
[Errno 2] No such file or directory: '/dbtlearn/seeds/full_moon_dates.csv'
[0m14:38:48  1 of 1 ERROR loading seed file DEV.full_moon_dates ............................. [[31mERROR[0m in 0.03s]
[0m14:38:48
[0m14:38:48  Finished running 1 seed in 0 hours 0 minutes and 2.32 seconds (2.32s).
[0m14:38:48
[0m14:38:48  [31mCompleted with 1 error and 0 warnings:[0m
[0m14:38:48
[0m14:38:48  [33m[Errno 2] No such file or directory: '/dbtlearn/seeds/full_moon_dates.csv'[0m
[0m14:38:48
[0m14:38:48  Done. PASS=0 WARN=0 ERROR=1 SKIP=0 TOTAL=1
[2024-07-10 14:38:48,993] {taskinstance.py:1400} INFO - Marking task as FAILED. dag_id=create_layers_in_snowflake, task_id=create_seeds, execution_date=20240710T143842, start_date=20240710T143843, end_date=20240710T143848
[2024-07-10 14:38:49,028] {standard_task_runner.py:97} ERROR - Failed to execute job 26 for task create_seeds (Docker container failed: {'StatusCode': 1} lines total 8
drwxr-xr-x 10 root root 4096 Jul 10 00:27 dbtlearn
-rw-r--r--  1 root root   55 Jul  9 18:41 requirements.txt
total 12
drwxrwxrwx 1 root root 4096 Jul 10 00:27 dbtlearn
-rw-r--r-- 1 root root   55 Jul  9 18:41 requirements.txt
total 72
-rwxrwxrwx 1 root root  571 Jul 10 00:27 README.md
drwxrwxrwx 1 root root 4096 Jul 10 00:27 dbt_packages
-rwxrwxrwx 1 root root 1237 Jul 10 00:27 dbt_project.yml
drwxrwxrwx 1 root root 4096 Jul 10 00:27 logs
drwxrwxrwx 1 root root 4096 Jul 10 00:27 macros
drwxrwxrwx 1 root root 4096 Jul 10 00:27 models
-rwxrwxrwx 1 root root  255 Jul 10 00:27 profiles.yml
drwxrwxrwx 1 root root 4096 Jul 10 00:27 seeds
drwxrwxrwx 1 root root 4096 Jul 10 00:27 snapshots
drwxrwxrwx 1 root root 4096 Jul 10 00:27 target
drwxrwxrwx 1 root root 4096 Jul 10 00:27 tests
total 4
-rwxrwxrwx 1 root root 3007 Jul 10 00:27 full_moon_dates.csv
[0m14:38:45  Running with dbt=1.5.0
[0m14:38:45  Found 9 models, 0 tests, 0 snapshots, 0 analyses, 321 macros, 0 operations, 1 seed file, 0 sources, 0 exposures, 0 metrics, 0 groups
[0m14:38:45
[0m14:38:48  Concurrency: 1 threads (target='dev')
[0m14:38:48
[0m14:38:48  1 of 1 START seed file DEV.full_moon_dates ..................................... [RUN]
[0m14:38:48  [31mUnhandled error while executing [0m
[Errno 2] No such file or directory: '/dbtlearn/seeds/full_moon_dates.csv'
[0m14:38:48  1 of 1 ERROR loading seed file DEV.full_moon_dates ............................. [[31mERROR[0m in 0.03s]
[0m14:38:48
[0m14:38:48  Finished running 1 seed in 0 hours 0 minutes and 2.32 seconds (2.32s).
[0m14:38:48
[0m14:38:48  [31mCompleted with 1 error and 0 warnings:[0m
[0m14:38:48
[0m14:38:48  [33m[Errno 2] No such file or directory: '/dbtlearn/seeds/full_moon_dates.csv'[0m
[0m14:38:48
[0m14:38:48  Done. PASS=0 WARN=0 ERROR=1 SKIP=0 TOTAL=1; 2806)
[2024-07-10 14:38:49,071] {local_task_job.py:156} INFO - Task exited with return code 1
[2024-07-10 14:38:49,154] {local_task_job.py:273} INFO - 0 downstream tasks scheduled from follow-on schedule check
