[2024-07-10 13:52:19,302] {taskinstance.py:1159} INFO - Dependencies all met for <TaskInstance: create_layers_in_snowflake.create_seeds manual__2024-07-10T13:50:46.314196+00:00 [success]>
[2024-07-10 13:52:19,303] {taskinstance.py:1159} INFO - Dependencies all met for <TaskInstance: create_layers_in_snowflake.create_seeds manual__2024-07-10T13:50:46.314196+00:00 [success]>
[2024-07-10 13:52:19,303] {taskinstance.py:1356} INFO - 
--------------------------------------------------------------------------------
[2024-07-10 13:52:19,304] {taskinstance.py:1357} INFO - Starting attempt 2 of 1
[2024-07-10 13:52:19,304] {taskinstance.py:1358} INFO - 
--------------------------------------------------------------------------------
[2024-07-10 13:52:19,319] {taskinstance.py:1377} INFO - Executing <Task(DockerOperator): create_seeds> on 2024-07-10 13:50:46.314196+00:00
[2024-07-10 13:52:19,323] {standard_task_runner.py:52} INFO - Started process 587 to run task
[2024-07-10 13:52:19,327] {standard_task_runner.py:79} INFO - Running: ['***', 'tasks', 'run', 'create_layers_in_snowflake', 'create_seeds', 'manual__2024-07-10T13:50:46.314196+00:00', '--job-id', '8', '--pool', 'default_pool', '--raw', '--subdir', 'DAGS_FOLDER/create_layers.py', '--cfg-path', '/tmp/tmp4675c_6i', '--error-file', '/tmp/tmpakio35ay']
[2024-07-10 13:52:19,328] {standard_task_runner.py:80} INFO - Job 8: Subtask create_seeds
[2024-07-10 13:52:19,408] {task_command.py:369} INFO - Running <TaskInstance: create_layers_in_snowflake.create_seeds manual__2024-07-10T13:50:46.314196+00:00 [running]> on host bc9f9d1e47b7
[2024-07-10 13:52:19,487] {taskinstance.py:1571} INFO - Exporting the following env vars:
AIRFLOW_CTX_DAG_OWNER=***
AIRFLOW_CTX_DAG_ID=create_layers_in_snowflake
AIRFLOW_CTX_TASK_ID=create_seeds
AIRFLOW_CTX_EXECUTION_DATE=2024-07-10T13:50:46.314196+00:00
AIRFLOW_CTX_TRY_NUMBER=2
AIRFLOW_CTX_DAG_RUN_ID=manual__2024-07-10T13:50:46.314196+00:00
[2024-07-10 13:52:19,513] {docker.py:247} INFO - Starting docker container from image custom_dbt_image
[2024-07-10 13:52:19,657] {docker.py:308} INFO - sh: 1: cd: can't cd to /dbtlearn
[2024-07-10 13:52:19,710] {taskinstance.py:1889} ERROR - Task failed with exception
Traceback (most recent call last):
  File "/home/airflow/.local/lib/python3.7/site-packages/airflow/providers/docker/operators/docker.py", line 387, in execute
    return self._run_image()
  File "/home/airflow/.local/lib/python3.7/site-packages/airflow/providers/docker/operators/docker.py", line 266, in _run_image
    return self._run_image_with_mounts(self.mounts, add_tmp_variable=False)
  File "/home/airflow/.local/lib/python3.7/site-packages/airflow/providers/docker/operators/docker.py", line 313, in _run_image_with_mounts
    raise AirflowException(f'Docker container failed: {repr(result)} lines {joined_log_lines}')
airflow.exceptions.AirflowException: Docker container failed: {'StatusCode': 2} lines sh: 1: cd: can't cd to /dbtlearn
[2024-07-10 13:52:19,714] {taskinstance.py:1400} INFO - Marking task as FAILED. dag_id=create_layers_in_snowflake, task_id=create_seeds, execution_date=20240710T135046, start_date=20240710T135219, end_date=20240710T135219
[2024-07-10 13:52:19,724] {standard_task_runner.py:97} ERROR - Failed to execute job 8 for task create_seeds (Docker container failed: {'StatusCode': 2} lines sh: 1: cd: can't cd to /dbtlearn; 587)
[2024-07-10 13:52:19,753] {local_task_job.py:156} INFO - Task exited with return code 1
[2024-07-10 13:52:19,790] {local_task_job.py:273} INFO - 0 downstream tasks scheduled from follow-on schedule check
