[2024-07-09 23:48:41,915] {taskinstance.py:1159} INFO - Dependencies all met for <TaskInstance: create_layers_in_snowflake.create_seeds manual__2024-07-09T23:48:40.893961+00:00 [queued]>
[2024-07-09 23:48:41,925] {taskinstance.py:1159} INFO - Dependencies all met for <TaskInstance: create_layers_in_snowflake.create_seeds manual__2024-07-09T23:48:40.893961+00:00 [queued]>
[2024-07-09 23:48:41,925] {taskinstance.py:1356} INFO - 
--------------------------------------------------------------------------------
[2024-07-09 23:48:41,926] {taskinstance.py:1357} INFO - Starting attempt 1 of 1
[2024-07-09 23:48:41,926] {taskinstance.py:1358} INFO - 
--------------------------------------------------------------------------------
[2024-07-09 23:48:41,939] {taskinstance.py:1377} INFO - Executing <Task(DockerOperator): create_seeds> on 2024-07-09 23:48:40.893961+00:00
[2024-07-09 23:48:41,943] {standard_task_runner.py:52} INFO - Started process 1281 to run task
[2024-07-09 23:48:41,947] {standard_task_runner.py:79} INFO - Running: ['***', 'tasks', 'run', 'create_layers_in_snowflake', 'create_seeds', 'manual__2024-07-09T23:48:40.893961+00:00', '--job-id', '18', '--raw', '--subdir', 'DAGS_FOLDER/create_layers.py', '--cfg-path', '/tmp/tmprk7cillw', '--error-file', '/tmp/tmpx9u7q80n']
[2024-07-09 23:48:41,967] {standard_task_runner.py:80} INFO - Job 18: Subtask create_seeds
[2024-07-09 23:48:42,023] {task_command.py:369} INFO - Running <TaskInstance: create_layers_in_snowflake.create_seeds manual__2024-07-09T23:48:40.893961+00:00 [running]> on host a22086a40575
[2024-07-09 23:48:42,096] {taskinstance.py:1571} INFO - Exporting the following env vars:
AIRFLOW_CTX_DAG_OWNER=***
AIRFLOW_CTX_DAG_ID=create_layers_in_snowflake
AIRFLOW_CTX_TASK_ID=create_seeds
AIRFLOW_CTX_EXECUTION_DATE=2024-07-09T23:48:40.893961+00:00
AIRFLOW_CTX_TRY_NUMBER=1
AIRFLOW_CTX_DAG_RUN_ID=manual__2024-07-09T23:48:40.893961+00:00
[2024-07-09 23:48:42,119] {docker.py:247} INFO - Starting docker container from image custom_dbt_image
[2024-07-09 23:48:42,128] {taskinstance.py:1889} ERROR - Task failed with exception
Traceback (most recent call last):
  File "/home/airflow/.local/lib/python3.7/site-packages/docker/api/client.py", line 268, in _raise_for_status
    response.raise_for_status()
  File "/home/airflow/.local/lib/python3.7/site-packages/requests/models.py", line 960, in raise_for_status
    raise HTTPError(http_error_msg, response=self)
requests.exceptions.HTTPError: 400 Client Error: Bad Request for url: http+docker://localhost/v1.45/containers/create

During handling of the above exception, another exception occurred:

Traceback (most recent call last):
  File "/home/airflow/.local/lib/python3.7/site-packages/airflow/providers/docker/operators/docker.py", line 387, in execute
    return self._run_image()
  File "/home/airflow/.local/lib/python3.7/site-packages/airflow/providers/docker/operators/docker.py", line 254, in _run_image
    return self._run_image_with_mounts(self.mounts + [tmp_mount], add_tmp_variable=True)
  File "/home/airflow/.local/lib/python3.7/site-packages/airflow/providers/docker/operators/docker.py", line 298, in _run_image_with_mounts
    tty=self.tty,
  File "/home/airflow/.local/lib/python3.7/site-packages/docker/api/container.py", line 428, in create_container
    return self.create_container_from_config(config, name)
  File "/home/airflow/.local/lib/python3.7/site-packages/docker/api/container.py", line 439, in create_container_from_config
    return self._result(res, True)
  File "/home/airflow/.local/lib/python3.7/site-packages/docker/api/client.py", line 274, in _result
    self._raise_for_status(response)
  File "/home/airflow/.local/lib/python3.7/site-packages/docker/api/client.py", line 270, in _raise_for_status
    raise create_api_error_from_http_exception(e)
  File "/home/airflow/.local/lib/python3.7/site-packages/docker/errors.py", line 31, in create_api_error_from_http_exception
    raise cls(e, response=response, explanation=explanation)
docker.errors.APIError: 400 Client Error for http+docker://localhost/v1.45/containers/create: Bad Request ("invalid mount config for type "bind": bind source path does not exist: /usr/app/dbtlearn")
[2024-07-09 23:48:42,138] {taskinstance.py:1400} INFO - Marking task as FAILED. dag_id=create_layers_in_snowflake, task_id=create_seeds, execution_date=20240709T234840, start_date=20240709T234841, end_date=20240709T234842
[2024-07-09 23:48:42,149] {standard_task_runner.py:97} ERROR - Failed to execute job 18 for task create_seeds (400 Client Error for http+docker://localhost/v1.45/containers/create: Bad Request ("invalid mount config for type "bind": bind source path does not exist: /usr/app/dbtlearn"); 1281)
[2024-07-09 23:48:42,169] {local_task_job.py:156} INFO - Task exited with return code 1
[2024-07-09 23:48:42,202] {local_task_job.py:273} INFO - 0 downstream tasks scheduled from follow-on schedule check
